# Excepciones

Los errores de ejecución son llamados comúnmente excepciones y por eso de
ahora en más utilizaremos ese nombre. Durante la ejecución de un programa, si
dentro de una función surge una excepción y la función no la maneja, la
excepción se propaga hacia la función que la invocó, si esta otra tampoco la
maneja, la excepción continúa propagándose hasta llegar a la función inicial del
programa y si esta tampoco la maneja se interrumpe la ejecución del programa.

Veamos entonces cómo manejar excepciones.

Para el manejo de excepciones los lenguajes proveen ciertas palabras
reservadas, que nos permiten manejar las excepciones que puedan surgir y
tomar acciones de recuperación para evitar la interrupción del programa o, al
menos, para realizar algunas acciones adicionales antes de interrumpir el
programa.

En el caso de Python, el manejo de excepciones se hace mediante los bloques
que utilizan las sentencias try, except,else y finally.

    num1=10
    num2=0
    res= num1/num2
    res
    
salida

    ZeroDivisionError: division by zero
    
En este caso, se levantó la excepción ZeroDivisionError cuando se quiso hacer
la división. Para evitar que se levante la excepción y se detenga la ejecución del
programa, se utiliza el bloque try-except.

    num1=10
    num2=0

    try:
      res= num1/num2

    except:
      print('no es posible dividir entre 0')
      
salida

    no es posible dividir entre 0
    
otro ejemplo

    try:
        f = open('fichero.txt')  # El fichero no existe
    except:  #estamos estableciendo que para cualquier exepcion, podriamos ser más específicos para evitar tener confusión
        print('¡El fichero no existe!')
    else:
        print(f.read())
        
 salida
 
    ¡El fichero no existe!
    
    
otro ejemplo

while True:

       try:
         x = int(input("Ingresa un número: "))
         break
       except ValueError: #aquí la establecemos para que tipo de exepcion
        print("Oops!  Ese no es un dato valido.  Ingresa de nuevo...")


Dado que dentro de un mismo bloque try pueden producirse excepciones de
distinto tipo, es posible utilizar varios bloques except, cada uno para capturar un
tipo distinto de excepción.

Esto se hace especificando a continuación de la sentencia except el nombre de
la excepción que se pretende capturar. Un mismo bloque except puede atrapar
varios tipos de excepciones, lo cual se hace especificando los nombres de la
excepciones separados por comas a continuación de la palabra except. Es
importante destacar que si bien luego de un bloque try puede haber varios
bloques except, se ejecutará, a lo sumo, uno de ellos.

## Tipos de excepciones
Los principales excepciones definidas en Python son:

* TypeError : Ocurre cuando se aplica una operación o función a un dato del tipo inapropiado.
* ZeroDivisionError : Ocurre cuando se itenta dividir por cero.
* OverflowError : Ocurre cuando un cálculo excede el límite para un tipo de dato numérico.
* IndexError : Ocurre cuando se intenta acceder a una secuencia con un índice que no existe.
* KeyError : Ocurre cuando se intenta acceder a un diccionario con una clave que no existe.
* FileNotFoundError : Ocurre cuando se intenta acceder a un fichero que no existe en la ruta indicada.
* ImportError : Ocurre cuando falla la importación de un módulo.

Es posible, por otra parte, que luego de realizar algún procesamiento particular del caso se quiera que la excepción se propague hacia la función que había invocado a la función actual. Para hacer esto Python nos brinda la instrucción raise.

En una funcion

     def division(a, b):
        try:
           result = a / b
        except:
            print('¡No se puede dividir por cero!')
        else:
            print(result)
            
     division(10,0)
     
salida

    ¡No se puede dividir por cero!
            
    
otro ejemplo:

        while True:
            try:
                edad = int(input("Escribe tu edad: "))
                break
            except ValueError:
                print("¡Debes ingresar un número!")

        if edad >= 18:
            print("Eres un adulto.")
        else:
            print("Aún no eres un adulto.")
